[2025-06-05T07:19:36.725+0000] {task_context_logger.py:104} WARNING - Marking task instance <TaskInstance: gold_price_pipeline.extract_gold_price manual__2025-06-05T07:07:52.464147+00:00 [queued]> stuck in queued as failed. If the task instance has available retries, it will be retried.
[2025-06-05T07:19:37.574+0000] {task_context_logger.py:104} ERROR - Executor reports task instance <TaskInstance: gold_price_pipeline.extract_gold_price manual__2025-06-05T07:07:52.464147+00:00 [queued]> finished (failed) although the task says it's queued. (Info: None) Was the task killed externally?
